Workbook
Name AgentPattern: _Lists!$D$2:$D$8
Name AgentStatus: _Lists!$A$2:$A$9
Name Autonomy: _Lists!$B$2:$B$7
Name ChargingBasis: _Lists!$K$2:$K$10
Name Complexity: _Lists!$F$2:$F$5
Name Confidence: _Lists!$N$2:$N$8
Name CostClass: _Lists!$J$2:$J$10
Name Currency: _Lists!$P$2:$P$9
Name Environment: _Lists!$Q$2:$Q$9
Name EvidenceType: _Lists!$O$2:$O$8
Name Frequency: _Lists!$L$2:$L$7
Name Hosting: _Lists!$R$2:$R$6
Name Inclusion: _Lists!$M$2:$M$7
Name InputSource: _Lists!$I$2:$I$8
Name ModelClass: _Lists!$S$2:$S$8
Name Owner: _Lists!$T$2:$T$7
Name Scenario: _Lists!$H$2:$H$7
Name SolutionType: _Lists!$C$2:$C$4
Name Technology: _Lists!$E$2:$E$6
Name ValidationStatus: _Lists!$U$2:$U$7
Name YesNo: _Lists!$G$2:$G$4

Sheet Instructions
A1: AMS RFP | AI Agent Cost Estimator | Bidder Instructions
A2: Purpose: capture a consistent, auditable and comparable partner submission linking every AI-enabled AMS capability to demand, consumption, cost, benefit and supporting evidence, while retaining the existing normalized monthly cost model.
A4: 1. NON-NEGOTIABLE SUBMISSION RULES
A5: 1 | B5: Use one unique Agent ID across AI_Agent_Inventory, Demand_Scenarios, AI_Consumption, Cost_Register and Benefits.
A6: 2 | B6: Enter data only in blue-font/yellow-fill cells. Do not overwrite formulas, linked cells, summaries, charts or controlled lists.
A7: 3 | B7: Provide all five scenarios: Minimum adoption, Expected case, High adoption, Peak/stress case and PepsiCo standard.
A8: 4 | B8: Use one reporting currency and disclose source, region, SKU/version, effective date, discount, markup, term, escalation and pricing validity.
A9: 5 | B9: Enter every cost once. Avoid duplication across Unit_Costs, Cost_Register, Infra_Sizing, Staffing, licenses, platform services and pass-through charges.
A10: 6 | B10: Explain required blanks, zero values, exclusions, dependencies, minimum commitments, optional items and PepsiCo-funded components.
A11: 7 | B11: Reference supporting document or artifact names, file links, pricing sources or attachment IDs in each Evidence Reference / Pricing Source field, and select the appropriate Input Source.
A12: 8 | B12: Retain all remaining worksheets, formulas, validations and sheet names. The hidden _Lists sheet must not be modified.
A14: 2. REQUIRED COMPLETION SEQUENCE
A15: Step | B15: Sheet | C15: Primary owner | D15: Type | E15: What the bidder must enter or review | F15: Completion test | G15: Key control | H15: Partner Action
A16: 1 | B16: AI_Agent_Inventory | C16: AI / solution lead | D16: Sheet within this document | E16: Enter one row per AI-enabled capability: identity, scope, status, autonomy, pattern, technology, complexity, instances, controls, ownership, hosting and evidence. | F16: Every proposed capability has one unique Agent ID. | G16: Reuse the Agent ID in every connected sheet. | H16: Input
A17: 2 | B17: Demand_Scenarios | C17: Service / process owner | D17: Sheet within this document | E17: Enter one row per Agent ID and scenario: trigger unit, eligible volume, adoption, executions, retries, outcomes, peak, concurrency, runtime, growth and rollout. | F17: All five scenarios exist for every priced capability. | G17: Enter percentages as rates, for example 25%, not 25. | H17: Input
A18: 3 | B18: AI_Consumption | C18: AI architect / FinOps | D18: Sheet within this document | E18: Enter one row per Agent ID, scenario and model/service: routing, calls, tokens, caching, retries, AI services, prices and commercial terms. | F18: Consumption and prices are traceable to design or evidence. | G18: Do not duplicate system prompt, retrieval/tool or retry consumption. | H18: Input
A19: 4 | B19: Assumptions | C19: Estimator | D19: Sheet within this document | E19: Complete normalized monthly timeline, rollout, adoption, workload, LLM behavior, token sizing and token prices. | F19: Inputs align with the proposed rollout and monthly model. | G19: Explain differences from Demand_Scenarios. | H19: Input
A20: 5 | B20: Unit_Costs | C20: Platform / FinOps | D20: Sheet within this document | E20: Enter normalized platform, data, observability and licensing rates in the units shown; complete Notes / Source. | F20: Rates use a consistent currency, region, SKU and pricing basis. | G20: Do not duplicate rates or costs in Cost_Register. | H20: Input
A21: 6 | B21: Cost_Register | C21: Commercial / FinOps | D21: Sheet within this document | E21: Enter each cost component once with one mandatory classification, charging basis, quantity, rate, frequency, inclusion, Years 1–5 quantities, source and evidence. | F21: Net rate and Years 1–5 costs reconcile to the offer. | G21: Do not overwrite formula columns; document shared-cost allocation. | H21: Input + formulas
A22: 7 | B22: Infra_Sizing | C22: Cloud architect | D22: Sheet within this document | E22: Enter baseline capacity, fixed/shared services and networking/security overhead for the monthly model. | F22: Capacity and environments match the architecture. | G22: Avoid costs already embedded in blended rates or Cost_Register. | H22: Input
A23: 8 | B23: Staffing | C23: Service delivery lead | D23: Sheet within this document | E23: Enter incremental operator FTEs, loaded cost and pod allocation, or document exclusion/inclusion in AMS. | F23: Pod allocation equals total FTEs and matches the service model. | G23: Do not duplicate labor included in another cost line. | H23: Input if applicable
A24: 9 | B24: Benefits | C24: Value lead | D24: Sheet within this document | E24: Enter measurable outcomes, baseline, target, formula, financial value, confidence, commitment, validation, dependencies and attribution control. | F24: Benefits are measurable and evidence-referenced. | G24: Prevent overlap across agents, towers and labor productivity. | H24: Input
A25: Supporting evidence | B25: Architecture / Risk / Commercial | C25: External RFP attachments / bidder repository | D25: Provide supporting architecture, pricing, delivery, control, operations and boundary artifacts outside this workbook; reference the exact document name, attachment ID or accessible link in each relevant Evidence Reference field. | E25: Every material Evidence Reference or Pricing Source points to a supplied artifact or authoritative source. | F25: Identify access restrictions, open gaps and resolution dates in Notes / Exclusions or the bidder response. | G25: Input / reference | H25: Input
A26: 11 | B26: LLM_Calc / Observability | C26: Estimator / reviewers | D26: Sheet within this document | E26: Review selected-month token, AI-service, logging and dashboard outputs. | F26: Outputs move logically with demand and unit rates. | G26: Do not type over formulas. | H26: Review only
A27: 12 | B27: Model_Monthly / Summary / Charts | C27: Estimator / reviewers | D27: Sheet within this document | E27: Review the normalized monthly platform, run-cost, staffing and executive outputs. | F27: Monthly outputs reconcile to Assumptions, Unit_Costs, Infra_Sizing and Staffing. | G27: This remains the normalized monthly view. | H27: Review only
A28: 13 | B28: Five_Year_TCO | C28: Commercial lead + reviewers | D28: Sheet within this document | E28: Review Years 1–5 cost by scenario/classification, benefit, net benefit, unit economics and variance to PepsiCo standard. | F28: Totals reconcile to Cost_Register, Benefits and the bid. | G28: Resolve material zero values and variances before submission. | H28: Review only
A29: 14 | B29: Final certification | C29: Authorized representative | D29: Recommendation for bidders | E29: Confirm formula visibility, completeness, availability status, exclusions, dependencies, ownership, portability, exit treatment and validity. | F29: Submission is complete and ready for normalization. | G29: Retain workbook structure and calculation lineage. | H29: Certification
A32: 3. INPUT AND CALCULATION CONVENTIONS
A33: Blue font / yellow fill | B33: Bidder-editable input requiring completion or a documented non-applicability statement.
A34: Green fill / black font | B34: Formula-driven or linked cell. Do not overwrite.
A35: Asterisk (*) | B35: Mandatory field for a completed row.
A36: Shared costs | B36: Use Agent ID / Shared = Shared and explain the allocation method.
A37: Headless agents | B37: Use the documented trigger or invocation unit. Do not automatically equate trigger, execution, run and LLM call.
A38: Demand formula | B38: Annual executions = eligible monthly volume × eligible % × adoption % × executions per eligible unit × 12, with documented adjustments only.
A39: Net unit rate | B39: Gross unit rate × (1 − discount %) × (1 + partner markup %).
A40: Five-year cost | B40: Each year cost = that year quantity × net unit rate; Five-Year Cost = sum of Years 1–5.
A41: Benefits | B41: State baseline, target, formula, validation source, confidence, commitment, dependencies and overlap control.
A42: Unit economics | B42: Use the same scenario population and period in the cost numerator and volume/outcome denominator.
A44: 4. FINAL RECONCILIATION CHECKLIST
A45: ☑ | B45: Agent IDs reconcile across AI_Agent_Inventory, Demand_Scenarios, AI_Consumption, Cost_Register and Benefits.
...

Sheet AI_Agent_Inventory
A1: AMS RFP | AI Agent Inventory
A2: BIDDER INPUT: One row per proposed AI-enabled capability. Use the same unique Agent ID in all technical, cost, benefit and evidence sheets.
A4: Agent ID* | B4: Agent Name* | C4: Description* | D4: AMS Tower* | E4: Application Scope* | F4: Business Process | G4: Use-case Category | H4: Supported Languages | I4: Capability Status* | J4: Autonomy* | K4: User/Headless* | L4: Agent Pattern* | M4: Technology* | N4: Complexity* | O4: Logical Agents | P4: Deployed Instances | Q4: Markets / BUs | R4: Environments | S4: Systems Updated | T4: Human Approval Gate | U4: Kill Switch | V4: Rollback / Override | W4: Code Owner | X4: Prompt / Workflow Owner | Y4: Data / Logs Owner | Z4: Hosting Model | AA4: Evidence Reference | AB4: Assumption Source* | AC4: Notes | AD4: Subagents
A5: AIA-001 | B5: Incident Triage Copilot | C5: Classifies, enriches and routes incidents using service context and knowledge. | D5: Service Desk | E5: Enterprise applications | F5: Incident management | G5: Triage and routing | H5: English, French, Spanish | I5: Configurable existing capability | J5: Recommendation-based | K5: User-facing | L5: Domain agent | M5: Agentic AI | N5: Medium | O5: 1 | P5: 3 | Q5: UK, EMEA, India | R5: Development, Test, Production | S5: ServiceNow | T5: Yes | U5: Yes | V5: Assignment group override | W5: Partner | X5: Joint | Y5: PepsiCo | Z5: Hybrid | AA5: Architecture Pack AP-01; Control Matrix CM-01 | AB5: Partner-estimated | AC5: Human approval required for priority and resolver changes. | AD5: 15 proposed-agent entries: Triage Agent [POC Completed]; Categorization of Incident [In Prod]; Incident-copilot Agent [POC Completed]; Isummarizer BOT [Pilot]; Intake Agent [POC Completed]; Ticket Hygiene Agent [POC Completed]; Incident-copilot Agent WM [POC Completed]; Triage Agent WM [POC Completed]; MIM Agent [Pilot]; Agent Sherlock (L3 Triage Agent) [Pilot]; Communication Agent [POC Completed]; Ticket Creation Automation Agent [In Prod]; Email Processing Agent [In Prod]; Outlook Inbox Automation Agent [POC Completed]; Intelligent Incident Agent [Pilot]
A6: AIA-002 | B6: Safe Auto-Remediation Agent | C6: Executes approved runbooks for repeatable infrastructure and application faults. | D6: Cloud & Infrastructure | E6: Azure and hosted applications | F6: Incident resolution | G6: Self-healing | H6: English | I6: Reusable accelerator | J6: Bounded autonomous execution | K6: Headless | L6: Orchestration agent | M6: Blended | N6: Complex | O6: 3 | P6: 6 | Q6: UK, EMEA, India | R6: Development, Test, Production, DR | S6: Azure, ServiceNow | T6: Yes | U6: Yes | V6: Runbook rollback and manual stop | W6: Partner | X6: Partner | Y6: PepsiCo | Z6: PepsiCo-hosted | AA6: Architecture Pack AP-02; Runbook Catalogue RC-01 | AB6: Partner-estimated | AC6: Only allow-listed actions; privileged access via managed identity. | AD6: 27 proposed-agent entries: Data Management Agent [POC Completed]; Nexthink Automation Agent [In Prod]; Intelligent Ticket Resolution [POC Completed]; PR Deletion – Old Purchase Requisition Deletions [In Prod]; Auto log Analyzer and Resolution Agent [In Prod]; Moveit Service - Start and Stop Services [In Prod]; Cross Reference Manager Agent [POC Completed]; Ticket Update Automation Agent [In Prod]; Sales order completed still demand showing in MD04 [In Prod]; PFNA Data Sync issue fixer & Reconciliation Agent [To be custom built for PepsiCo]; DataQualitySentinel [To be custom built for PepsiCo]; PFNA Alerts Remediation Agent [To be custom built for PepsiCo]; PACE- Invoice Reconciler and Reprocesseser [To be custom built for PepsiCo]; GTMS_EXCEPTION_LOG_SYNC_AGENT [To be custom built for PepsiCo]; WMS- Stock Integrity Agent [To be custom built for PepsiCo]; PACE- DataQualitySentinel [To be custom built for PepsiCo]; PACE- Stock Integrity Agent [To be custom built for PepsiCo]; PEPSICOSELL_MASTER_CONFIG_AGENT [To be custom built for PepsiCo]; PEPSICOSELL_DATASYNC_AGENT [To be custom built for PepsiCo]; DELIVERSMARTR_DATASYNC_AGENT [To be custom built for PepsiCo]; PACE- RA-VAN Integrity Agent [To be custom built for PepsiCo]; PACE- Visit Exception Resolution Agent [To be custom built for PepsiCo]; PEPSICONNECT_DATASYNC_RECONCILIATION_AGENT [To be custom built for PepsiCo]; PEPSICONNECT_REWARD_ID_VERIFICATION_AGENT [To be custom built for PepsiCo]; PEPSICONNECT_DATA_SYNC_RECONCILIATION_AGENT [To be custom built for PepsiCo]; AMESA- Skelta WF Task Transfer [To be custom built for PepsiCo]; PBNA_STAR2_DATAFIX_AGENT [To be custom built for PepsiCo]
A7: AIA-003 | B7: Knowledge Resolution Copilot | C7: Retrieves governed knowledge and drafts resolution guidance with citations. | D7: Service Desk | E7: Enterprise applications | F7: Knowledge management | G7: Knowledge search and answer | H7: English, French, Spanish | I7: Production-proven | J7: Assistive | K7: User-facing | L7: Single-agent | M7: GenAI | N7: Medium | O7: 1 | P7: 3 | Q7: UK, EMEA, India | R7: Production | S7: ServiceNow, SharePoint | T7: Yes | U7: Yes | V7: Discard response and use standard search | W7: Partner | X7: Joint | Y7: PepsiCo | Z7: Hybrid | AA7: Architecture Pack AP-03; Knowledge Evaluation KE-01 | AB7: Benchmark-based | AC7: Answers restricted to approved indexed sources. | AD7: 15 proposed-agent entries: SOP Execution Agent [POC Completed]; MoMo Integration Chatbot [Pilot]; Support Assistant [Pilot]; Content Writer Agent [In Prod]; Knowledge Base (KB) Search with Guided Probing Agent [In Prod]; IRR - Incident Resolution Recommender [POC Completed]; AI Support Assistant [Pilot]; Intelligent Support Assistant [Pilot]; Resolution Notes Agent [In Prod]; Ask me Agent for business users [In Prod]; Snap.IO : Virtual Assistant [POC Completed]; DataGuard Agent [Pilot]; Rev-EAGLE [Pilot]; Knowledge Base Agent [POC Completed]; PEPSICONNECT_CONTENT_CONFIG_AGENT [To be custom built for PepsiCo]
A8: AIA-004 | B8: Service Request Fulfilment Agent | C8: Validates standard requests and orchestrates approved fulfilment workflows. | D8: Service Desk | E8: Service catalog | F8: Request fulfilment | G8: Workflow fulfilment | H8: English | I8: Configurable existing capability | J8: Human-approved execution | K8: User-facing | L8: Orchestration agent | M8: Blended | N8: Complex | O8: 2 | P8: 4 | Q8: UK, EMEA, India | R8: Test, Production | S8: ServiceNow, Entra ID | T8: Yes | U8: Yes | V8: Cancel workflow and restore prior state | W8: Partner | X8: Joint | Y8: PepsiCo | Z8: Hybrid | AA8: Architecture Pack AP-04; Workflow Catalogue WC-01 | AB8: Partner-estimated | AC8: Approval retained for access, spend and data changes. | AD8: 31 proposed-agent entries: TOMI [Pilot]; Intra-day Business KPI Reporting (Tapestry) [In Prod]; Scout Agent: [In Prod]; Rev-PULSE [Pilot]; Ticket Status Retrieval Agent [In Prod]; Service Request Creation Agent [In Prod]; Voice Channel Agent [In Prod]; Envision [In Prod]; Manufacturing Copilot [In Prod]; APAD [Pilot]; Forward a PO for Approval [In Prod]; Salesforce Agentforce(standard Query Data Capability) Agent [In Prod]; Email verfication and Delivery Agent [In Prod]; Accounts Payable Auto Invoice Generation Agent [In Prod]; Document Classification Agent [Pilot]; ABBYY_PO_ANALYZER_AGENT [To be custom built for PepsiCo]; TradeEdge-DiscountLens [To be custom built for PepsiCo]; PEPSICOSELL_Master_DATA_ROUTE_AGENT [To be custom built for PepsiCo]; FREEWEIGH_INSTALLISSUE_AGENT [To be custom built for PepsiCo]; PEPSICONNECT_SALES_TARGET_VALIDATION_AGENT [To be custom built for PepsiCo]; PEPSICONNECT_ORDER_FLOW_AGENT [To be custom built for PepsiCo]; PEPSICONNECT_INVOICE_PROCESS_VALIDATION_AGENT [To be custom built for PepsiCo]; PEPSICONNECT_MASTER_DATA_VALIDATION_AGENT [To be custom built for PepsiCo]; PEPSICONNECT_PROMOTION_PRODUCT_ENRICHMENT_AGENT [To be custom built for PepsiCo]; PEPSICONNECT_POINTS_TRANSFER_AGENT [To be custom built for PepsiCo]; PACE- Data Report Generator [To be custom built for PepsiCo]; PBNA_MODERENREPORT_DATAPULL_AGENT [To be custom built for PepsiCo]; PBNA_DELIVERY_DATAPULL_AGENT [To be custom built for PepsiCo]; PBNA_TPM_DATAPULL_AGENT [To be custom built for PepsiCo]; PBNA_TPM_ACCESS_AGENT [To be custom built for PepsiCo]; PBNA_STAR2_DATAPULL_AGENT [To be custom built for PepsiCo]
A9: AIA-005 | B9: Problem Trend Analyst | C9: Correlates recurring incidents and proposes problem records and known errors. | D9: Service Management | E9: Enterprise applications | F9: Problem management | G9: Trend and root-cause analysis | H9: English | I9: Reusable accelerator | J9: Recommendation-based | K9: User-facing | L9: Multi-agent | M9: Agentic AI | N9: Complex | O9: 3 | P9: 3 | Q9: UK, EMEA, India | R9: Production | S9: ServiceNow, Log Analytics | T9: Yes | U9: Yes | V9: Analyst rejects candidate problem | W9: Partner | X9: Partner | Y9: PepsiCo | Z9: Hybrid | AA9: Architecture Pack AP-05; Evaluation Report ER-01 | AB9: Benchmark-based | AC9: Correlation is advisory; problem manager owns publication. | AD9: 7 proposed-agent entries: RCA Agent [In Prod]; SNOW Incident Pattern Analyzer [POC Completed]; RCA finder for Incident [POC Completed]; Incident Triage and RCA Agent [POC Completed]; Issue Predictor & Root Cause Identifier [In Prod]; Root Cause Identifier Agent [In Prod]; PACE- Issue analyser [To be custom built for PepsiCo]
A10: AIA-006 | B10: Change Risk Advisor | C10: Scores change risk using history, dependencies, conflicts and test evidence. | D10: Change & Release | E10: Enterprise applications | F10: Change enablement | G10: Risk assessment | H10: English | I10: Configurable existing capability | J10: Recommendation-based | K10: User-facing | L10: Supervisor agent | M10: Agentic AI | N10: Highly complex | O10: 4 | P10: 3 | Q10: UK, EMEA, India | R10: Test, Production | S10: ServiceNow, Azure DevOps | T10: Yes | U10: Yes | V10: CAB override with rationale | W10: Partner | X10: Joint | Y10: PepsiCo | Z10: Hybrid | AA10: Architecture Pack AP-06; Risk Model RM-01 | AB10: Partner-estimated | AC10: No autonomous approval; CAB remains accountable. | AD10: 4 proposed-agent entries: Code Scanner Agent [POC Completed]; Supply Chain Trade Compliance Agent [In Prod]; SDLC Lifecycle Agents - Review Agent [Pilot]; PACE- EOT Compliance Agent [To be custom built for PepsiCo]
A11: AIA-007 | B11: Test Case Generation Copilot | C11: Generates traceable regression tests from requirements and change records. | D11: Application Engineering | E11: Retail and CPG applications | F11: Testing | G11: Test generation | H11: English | I11: Reusable accelerator | J11: Assistive | K11: User-facing | L11: Domain agent | M11: GenAI | N11: Medium | O11: 1 | P11: 3 | Q11: UK, EMEA, India | R11: Development, Test | S11: Azure DevOps | T11: Yes | U11: Yes | V11: Reviewer edits or rejects generated tests | W11: Partner | X11: Partner | Y11: PepsiCo | Z11: Partner-hosted | AA11: Architecture Pack AP-07; Quality Benchmark QB-01 | AB11: Benchmark-based | AC11: Generated tests require engineering review before execution. | AD11: 4 proposed-agent entries: Agent based UI Automation – QA [POC Completed]; AgentQ - Test Case Generator [POC Completed]; SDLC Lifecycle Agents - TST Agent [Pilot]; PACE- Smoke Test executor [To be custom built for PepsiCo]
A12: AIA-008 | B12: Release Validation Agent | C12: Checks release evidence, deployment health and rollback readiness. | D12: Change & Release | E12: Enterprise applications | F12: Release management | G12: Release assurance | H12: English | I12: Net-new build | J12: Human-approved execution | K12: Headless | L12: Supervisor agent | M12: Blended | N12: Complex | O12: 3 | P12: 3 | Q12: UK, EMEA, India | R12: Test, Production | S12: Azure DevOps, ServiceNow | T12: Yes | U12: Yes | V12: Stop deployment and invoke rollback | W12: Partner | X12: Joint | Y12: PepsiCo | Z12: Hybrid | AA12: Architecture Pack AP-08; Release Control RC-02 | AB12: Partner-estimated | AC12: Deployment gates remain deterministic and auditable. | AD12: 12 proposed-agent entries: SDLC Lifecycle Agents [Pilot]; Product Lifecycle Management Agent [Pilot] ×2; Job Scheduler Migration Agent [POC Completed]; SDLC Lifecycle Agents - Dev Agent [Pilot]; SDLC Lifecycle Agents - DB Agent [Pilot]; SDLC Lifecycle Agents - API Agent [Pilot]; SDLC Lifecycle Agents - FE Agent [Pilot]; SDLC Lifecycle Agents - Doc Agent [Pilot]; SDLC Lifecycle Agents - Orchestrator Agent [Pilot]; NA- Application Enhachement [To be custom built for PepsiCo]; PBNA_DELIVERY_CODEFIX_AGENT [To be custom built for PepsiCo]
A13: AIA-009 | B13: Event Correlation Agent | C13: Clusters alerts, suppresses duplicates and opens enriched incidents. | D13: Cloud & Infrastructure | E13: Azure and hosted applications | F13: Event management | G13: Alert correlation | H13: English | I13: Production-proven | J13: Bounded autonomous execution | K13: Headless | L13: Multi-agent | M13: Blended | N13: Complex | O13: 3 | P13: 6 | Q13: UK, EMEA, India | R13: Production, DR | S13: Azure Monitor, Splunk, ServiceNow | T13: Yes | U13: Yes | V13: Disable correlation rule and replay events | W13: Partner | X13: Partner | Y13: PepsiCo | Z13: PepsiCo-hosted | AA13: Architecture Pack AP-09; Operations Evidence OE-01 | AB13: Production reference | AC13: Auto-creation limited by confidence and severity thresholds. | AD13: 17 proposed-agent entries: Incident Management Agent [POC Completed]; Alert Verification System Agent [Pilot]; Observability Dashboard Agent [Pilot]; Incident Management Dashboard Agent [Pilot]; Observability Assistant [POC Completed]; Incident Intelligence Agent [Pilot]; Log Analyser Agent [Pilot]; Performance and Capacity Management [POC Completed]; Batch Health Analyzer [In Prod]; OCC Agent [POC Completed]; DigitalOpsAgent [In Prod]; Long Running Process Watchdog [POC Completed]; Execution Log Analyzer Agent [POC Completed]; High Volume Analyzer Agent [POC Completed]; ART Alert Insight Agent [Pilot]; GTMS_ALERT_OPTIMIZER_AGENT [To be custom built for PepsiCo]; PFNA Anomaly Detection Agent [To be custom built for PepsiCo]
A14: AIA-010 | B14: Access Request Assistant | C14: Guides users, validates entitlements and prepares access requests. | D14: Identity & Access | E14: Enterprise applications | F14: Access management | G14: Request assistance | H14: English, French, Spanish | I14: Configurable existing capability | J14: Human-approved execution | K14: User-facing | L14: Domain agent | M14: Agentic AI | N14: Complex | O14: 2 | P14: 3 | Q14: UK, EMEA, India | R14: Production | S14: ServiceNow, Entra ID | T14: Yes | U14: Yes | V14: Approver rejects; workflow revokes on error | W14: Partner | X14: Joint | Y14: PepsiCo | Z14: Hybrid | AA14: Architecture Pack AP-10; IAM Control IC-01 | AB14: Partner-estimated | AC14: No direct privileged access grant without owner approval. | AD14: 13 proposed-agent entries: Intelli Access Agent [Pilot]; Password reset & Incorrect intent recognition using ServiceNow NLU [In Prod]; User Access Agent Assist [In Prod]; SAVVY_USERPROFILE_AGENT [To be custom built for PepsiCo]; SAVVY_ACCESS_AGENT [To be custom built for PepsiCo]; DELIVERSMARTR_ACCESS_AGENT [To be custom built for PepsiCo]; PEPSICONNECT_PROFILE_MANAGEMENT_AGENT [To be custom built for PepsiCo]; AMESA- DB Role Configurator [To be custom built for PepsiCo]; PACE- User Activation & deactivation [To be custom built for PepsiCo]; FinOps- User Activation & deactivation [To be custom built for PepsiCo]; AMESA- App Dromant Users [To be custom built for PepsiCo]; PBNA_MODERENReport_ACCESS_AGENT [To be custom built for PepsiCo]; PBNA_DELIVERY_ACCESS_AGENT [To be custom built for PepsiCo]
A15: AIA-011 | B15: Business Data Integrity & Reconciliation Agent | C15: Detects, diagnoses, reconciles and corrects business-transaction and master-data inconsistencies across enterprise applications. Read-only analysis and write actions use separate control tiers, with data-owner approval, before-and-after evidence, duplicate prevention and rollback for changes.
A16: AIA-012 | B16: Interaction Orchestrator | C16: Provides omnichannel front door across chat, email, voice and shared mailboxes. It creates, updates and checks tickets and sends routine communications, then hands off triage, knowledge, fulfilment and access work to the appropriate super agent.
A17: AIA-013 | B17: Operations Reporting & Insights Agent | C17: Produces governed operational dashboards, incident summaries, performance and capacity forecasts, and high-volume execution insights. It is read-only and advisory, using approved KPI definitions and data lineage while source agents retain correlation and remediation ownership.
A18: AIA-014 | B18: Commercial Intelligence & Sales Enablement Copilot | C18: Provides governed commercial research, pricing and rate insights, and CRM or Salesforce business queries to support sales decisions. Tickets to IT team can be provided
A19: AIA-015 | B19: Customer Order Operations Orchestrator | C19: Coordinates routine customer-order operations such as order entry, validation, status progression and approved exception handling.
A20: AIA-016 | B20: Business Analytics & Data Query Copilot | C20: Enables governed business KPI reporting, natural-language or text-to-SQL queries and dashboard generation over certified datasets. It enforces semantic definitions, row-level security and data-owner controls and is distinct from AMS operational reporting.
A21: AIA-017 | B21: Finance & Accounts Payable Automation Agent | C21: Automates controlled finance and accounts-payable activities such as invoice extraction or generation, validation, matching and workflow preparation. Duplicate, tax and PO checks, segregation of duties and finance approval are required before posting.

Sheet Demand_Scenarios
A1: AMS RFP | Demand, Workload & Adoption
A2: BIDDER INPUT: Provide one row per Agent ID and required scenario. “Trigger Unit” may be incidents, requests, alerts, deployments, test cases, interactions or API runs.
A4: Agent ID* | B4: Scenario* | C4: Trigger Unit* | D4: Eligible Monthly Volume* | E4: Eligible %* | F4: Adoption %* | G4: Executions / Eligible Unit* | H4: Retry % * | I4: Success % * | J4: Autonomous Resolution % * | K4: Human Escalation % * | L4: Peak Multiplier | M4: Concurrency | N4: Avg Runtime (min) | O4: Monthly Growth % * | P4: Seasonality Factor | Q4: Rollout Start Month | R4: Input Source* | S4: Evidence Reference | T4: Notes
A5: AIA-001 | B5: Minimum adoption | C5: incidents | D5: 7000 | E5: 1 | F5: 0.25 | G5: 1 | H5: 0.04 | I5: 0.92 | J5: 0.25 | K5: 0.12 | L5: 1.3 | M5: 8 | N5: 1.8 | O5: 0.005 | P5: 1 | Q5: 1 | R5: Partner-estimated | S5: Demand Model DM-01; workload workshop pending | T5: Scenario-scaled partner estimate; validate against 12 months of source-system history. Demand executions exclude retry attempts; retry is applied once in AI consumption sizing.
A6: AIA-001 | B6: Expected case | C6: incidents | D6: 7000 | E6: 1 | F6: 0.6 | G6: 1 | H6: 0.06 | I6: 0.94 | J6: 0.45 | K6: 0.1 | L6: 1.6 | M6: 16 | N6: 1.8 | O6: 0.01 | P6: 1 | Q6: 1 | R6: Partner-estimated | S6: Demand Model DM-01; workload workshop pending | T6: Scenario-scaled partner estimate; validate against 12 months of source-system history. Demand executions exclude retry attempts; retry is applied once in AI consumption sizing.
A7: AIA-001 | B7: High adoption | C7: incidents | D7: 7000 | E7: 1 | F7: 0.8 | G7: 1 | H7: 0.08 | I7: 0.95 | J7: 0.6 | K7: 0.08 | L7: 1.9 | M7: 28 | N7: 1.8 | O7: 0.015 | P7: 1 | Q7: 1 | R7: Partner-estimated | S7: Demand Model DM-01; workload workshop pending | T7: Scenario-scaled partner estimate; validate against 12 months of source-system history. Demand executions exclude retry attempts; retry is applied once in AI consumption sizing.
A8: AIA-001 | B8: Peak/stress case | C8: incidents | D8: 7000 | E8: 1 | F8: 0.95 | G8: 1 | H8: 0.12 | I8: 0.93 | J8: 0.65 | K8: 0.12 | L8: 2.5 | M8: 45 | N8: 1.8 | O8: 0.02 | P8: 1 | Q8: 1 | R8: Partner-estimated | S8: Demand Model DM-01; workload workshop pending | T8: Scenario-scaled partner estimate; validate against 12 months of source-system history. Demand executions exclude retry attempts; retry is applied once in AI consumption sizing.
A9: AIA-001 | B9: PepsiCo standard | C9: incidents | D9: 7000 | E9: 1 | F9: 0.7 | G9: 1 | H9: 0.07 | I9: 0.95 | J9: 0.5 | K9: 0.09 | L9: 1.8 | M9: 20 | N9: 1.8 | O9: 0.01 | P9: 1 | Q9: 1 | R9: Assumption requiring validation | S9: Demand Model DM-01; workload workshop pending | T9: Placeholder standard case pending PepsiCo volume validation. Demand executions exclude retry attempts; retry is applied once in AI consumption sizing.
A10: AIA-002 | B10: Minimum adoption | C10: eligible incidents | D10: 500 | E10: 0.65 | F10: 0.25 | G10: 1 | H10: 0.04 | I10: 0.92 | J10: 0.25 | K10: 0.12 | L10: 1.3 | M10: 8 | N10: 4.5 | O10: 0.005 | P10: 1 | Q10: 2 | R10: Partner-estimated | S10: Demand Model DM-01; workload workshop pending | T10: Scenario-scaled partner estimate; validate against 12 months of source-system history. Demand executions exclude retry attempts; retry is applied once in AI consumption sizing.
A11: AIA-002 | B11: Expected case | C11: eligible incidents | D11: 500 | E11: 0.65 | F11: 0.6 | G11: 1 | H11: 0.06 | I11: 0.94 | J11: 0.45 | K11: 0.1 | L11: 1.6 | M11: 16 | N11: 4.5 | O11: 0.01 | P11: 1 | Q11: 2 | R11: Partner-estimated | S11: Demand Model DM-01; workload workshop pending | T11: Scenario-scaled partner estimate; validate against 12 months of source-system history. Demand executions exclude retry attempts; retry is applied once in AI consumption sizing.
A12: AIA-002 | B12: High adoption | C12: eligible incidents | D12: 500 | E12: 0.65 | F12: 0.8 | G12: 1 | H12: 0.08 | I12: 0.95 | J12: 0.6 | K12: 0.08 | L12: 1.9 | M12: 28 | N12: 4.5 | O12: 0.015 | P12: 1 | Q12: 2 | R12: Partner-estimated | S12: Demand Model DM-01; workload workshop pending | T12: Scenario-scaled partner estimate; validate against 12 months of source-system history. Demand executions exclude retry attempts; retry is applied once in AI consumption sizing.
A13: AIA-002 | B13: Peak/stress case | C13: eligible incidents | D13: 500 | E13: 0.65 | F13: 0.95 | G13: 1 | H13: 0.12 | I13: 0.93 | J13: 0.65 | K13: 0.12 | L13: 2.5 | M13: 45 | N13: 4.5 | O13: 0.02 | P13: 1 | Q13: 2 | R13: Partner-estimated | S13: Demand Model DM-01; workload workshop pending | T13: Scenario-scaled partner estimate; validate against 12 months of source-system history. Demand executions exclude retry attempts; retry is applied once in AI consumption sizing.
A14: AIA-002 | B14: PepsiCo standard | C14: eligible incidents | D14: 500 | E14: 0.65 | F14: 0.7 | G14: 1 | H14: 0.07 | I14: 0.95 | J14: 0.5 | K14: 0.09 | L14: 1.8 | M14: 20 | N14: 4.5 | O14: 0.01 | P14: 1 | Q14: 2 | R14: Assumption requiring validation | S14: Demand Model DM-01; workload workshop pending | T14: Placeholder standard case pending PepsiCo volume validation. Demand executions exclude retry attempts; retry is applied once in AI consumption sizing.
A15: AIA-003 | B15: Minimum adoption | C15: knowledge interactions | D15: 575 | E15: 0.9 | F15: 0.25 | G15: 1 | H15: 0.04 | I15: 0.92 | J15: 0.25 | K15: 0.12 | L15: 1.3 | M15: 8 | N15: 1.5 | O15: 0.005 | P15: 1 | Q15: 1 | R15: Partner-estimated | S15: Demand Model DM-01; workload workshop pending | T15: Scenario-scaled partner estimate; validate against 12 months of source-system history. Demand executions exclude retry attempts; retry is applied once in AI consumption sizing.
A16: AIA-003 | B16: Expected case | C16: knowledge interactions | D16: 575 | E16: 0.9 | F16: 0.6 | G16: 1 | H16: 0.06 | I16: 0.94 | J16: 0.45 | K16: 0.1 | L16: 1.6 | M16: 16 | N16: 1.5 | O16: 0.01 | P16: 1 | Q16: 1 | R16: Partner-estimated | S16: Demand Model DM-01; workload workshop pending | T16: Scenario-scaled partner estimate; validate against 12 months of source-system history. Demand executions exclude retry attempts; retry is applied once in AI consumption sizing.
... A54: AIA-010 | B54: PepsiCo standard | C54: access requests | D54: 1200 | E54: 0.8 | F54: 0.7 | G54: 1 | H54: 0.07 | I54: 0.95 | J54: 0.5 | K54: 0.09 | L54: 1.8 | M54: 20 | N54: 3 | O54: 0.01 | P54: 1 | Q54: 3 | R54: Assumption requiring validation | S54: Demand Model DM-01; workload workshop pending | T54: Placeholder standard case pending PepsiCo volume validation. Demand executions exclude retry attempts; retry is applied once in AI consumption sizing.
A55: AIA-011 | B55: Minimum adoption | C55: Incidents & Requests | D55: 2800 | E55: 0.8
A56: AIA-011 | B56: Expected case | C56: Incidents & Requests | D56: 2800 | E56: 0.8
A57: AIA-011 | B57: High adoption | C57: Incidents & Requests | D57: 2800 | E57: 0.8
A58: AIA-011 | B58: Peak/stress case | C58: Incidents & Requests | D58: 2800 | E58: 0.8
A59: AIA-011 | B59: PepsiCo standard | C59: Incidents & Requests | D59: 2800 | E59: 0.8
A60: AIA-012 | B60: Minimum adoption | C60: incidents | D60: 200 | E60: 0.8
A61: AIA-012 | B61: Expected case | C61: incidents | D61: 200 | E61: 0.8
A62: AIA-012 | B62: High adoption | C62: incidents | D62: 200 | E62: 0.8
A63: AIA-012 | B63: Peak/stress case | C63: incidents | D63: 200 | E63: 0.8
A64: AIA-012 | B64: PepsiCo standard | C64: incidents | D64: 200 | E64: 0.8
A65: AIA-013 | B65: Minimum adoption | C65: incidents | D65: 250 | E65: 0.8
A66: AIA-013 | B66: Expected case | C66: incidents | D66: 250 | E66: 0.8
... A89: AIA-017 | B89: PepsiCo standard | C89: Incidents & Requests | D89: 50 | E89: 0.8

Sheet AI_Consumption
A1: AMS RFP | LLM & AI Services Consumption
A2: BIDDER INPUT: One row per Agent ID, scenario and model/service. Capture routing, fallback, caching and contracted pricing. Do not duplicate retrieval/tool tokens.
A4: Agent ID* | B4: Scenario* | C4: Provider* | D4: Model / Service Name* | E4: Version / SKU | F4: Model Class* | G4: Primary / Fallback | H4: Hosting / Deployment | I4: Calls per Execution* | J4: Input Tokens / Call* | K4: Output Tokens / Call* | L4: System Prompt Tokens | M4: Retrieval / Tool Tokens | N4: Agent-to-Agent Exchanges | O4: Cache Hit % | P4: Retry % | Q4: Unit Price Input / 1M | R4: Unit Price Output / 1M | S4: Other Unit Price | T4: Other Unit of Measure | U4: Currency* | V4: Region | W4: Effective Date | X4: Enterprise Discount % | Y4: Partner Markup % | Z4: Minimum Commitment | AA4: Pricing Source / Evidence* | AB4: Input Source* | AC4: Notes
A5: AIA-001 | B5: Minimum adoption | C5: Microsoft Azure | D5: GPT-4.1 mini | E5: gpt-4.1-mini-2025-04-14 | F5: Small | G5: Primary | H5: Azure AI Foundry | I5: 2 | J5: 1800 | K5: 350 | L5: 500 | M5: 700 | N5: 0 | O5: 0.25 | P5: 0.04 | Q5: 0.4 | R5: 1.6 | S5: 0 | T5: N/A | U5: USD | V5: US benchmark | W5: 46298 | X5: 0 | Y5: 0 | Z5: 0 | AA5: OpenAI public API pricing benchmark; validate Azure AI Foundry enterprise rate | AB5: List price | AC5: No discount or markup assumed; regional Azure pricing and data-residency uplift require validation. Demand executions exclude retries; the Retry % here is the single consumption uplift. No minimum commitment assumed; pricing validity is unconfirmed pending the contracted Azure rate card.
A6: AIA-001 | B6: Expected case | C6: Microsoft Azure | D6: GPT-4.1 mini | E6: gpt-4.1-mini-2025-04-14 | F6: Small | G6: Primary | H6: Azure AI Foundry | I6: 2 | J6: 1800 | K6: 350 | L6: 500 | M6: 700 | N6: 0 | O6: 0.25 | P6: 0.06 | Q6: 0.4 | R6: 1.6 | S6: 0 | T6: N/A | U6: USD | V6: US benchmark | W6: 46298 | X6: 0 | Y6: 0 | Z6: 0 | AA6: OpenAI public API pricing benchmark; validate Azure AI Foundry enterprise rate | AB6: List price | AC6: No discount or markup assumed; regional Azure pricing and data-residency uplift require validation. Demand executions exclude retries; the Retry % here is the single consumption uplift. No minimum commitment assumed; pricing validity is unconfirmed pending the contracted Azure rate card.
A7: AIA-001 | B7: High adoption | C7: Microsoft Azure | D7: GPT-4.1 mini | E7: gpt-4.1-mini-2025-04-14 | F7: Small | G7: Primary | H7: Azure AI Foundry | I7: 2 | J7: 1800 | K7: 350 | L7: 500 | M7: 700 | N7: 0 | O7: 0.25 | P7: 0.08 | Q7: 0.4 | R7: 1.6 | S7: 0 | T7: N/A | U7: USD | V7: US benchmark | W7: 46298 | X7: 0 | Y7: 0 | Z7: 0 | AA7: OpenAI public API pricing benchmark; validate Azure AI Foundry enterprise rate | AB7: List price | AC7: No discount or markup assumed; regional Azure pricing and data-residency uplift require validation. Demand executions exclude retries; the Retry % here is the single consumption uplift. No minimum commitment assumed; pricing validity is unconfirmed pending the contracted Azure rate card.
A8: AIA-001 | B8: Peak/stress case | C8: Microsoft Azure | D8: GPT-4.1 mini | E8: gpt-4.1-mini-2025-04-14 | F8: Small | G8: Primary | H8: Azure AI Foundry | I8: 2 | J8: 1800 | K8: 350 | L8: 500 | M8: 700 | N8: 0 | O8: 0.25 | P8: 0.12 | Q8: 0.4 | R8: 1.6 | S8: 0 | T8: N/A | U8: USD | V8: US benchmark | W8: 46298 | X8: 0 | Y8: 0 | Z8: 0 | AA8: OpenAI public API pricing benchmark; validate Azure AI Foundry enterprise rate | AB8: List price | AC8: No discount or markup assumed; regional Azure pricing and data-residency uplift require validation. Demand executions exclude retries; the Retry % here is the single consumption uplift. No minimum commitment assumed; pricing validity is unconfirmed pending the contracted Azure rate card.
A9: AIA-001 | B9: PepsiCo standard | C9: Microsoft Azure | D9: GPT-4.1 mini | E9: gpt-4.1-mini-2025-04-14 | F9: Small | G9: Primary | H9: Azure AI Foundry | I9: 2 | J9: 1800 | K9: 350 | L9: 500 | M9: 700 | N9: 0 | O9: 0.25 | P9: 0.07 | Q9: 0.4 | R9: 1.6 | S9: 0 | T9: N/A | U9: USD | V9: US benchmark | W9: 46298 | X9: 0 | Y9: 0 | Z9: 0 | AA9: OpenAI public API pricing benchmark; validate Azure AI Foundry enterprise rate | AB9: List price | AC9: No discount or markup assumed; regional Azure pricing and data-residency uplift require validation. Demand executions exclude retries; the Retry % here is the single consumption uplift. No minimum commitment assumed; pricing validity is unconfirmed pending the contracted Azure rate card.
A10: AIA-002 | B10: Minimum adoption | C10: Microsoft Azure | D10: GPT-4.1 | E10: gpt-4.1-2025-04-14 | F10: Large | G10: Primary | H10: Azure AI Foundry | I10: 1.2 | J10: 5000 | K10: 900 | L10: 500 | M10: 700 | N10: 1 | O10: 0.25 | P10: 0.04 | Q10: 2 | R10: 8 | S10: 0 | T10: N/A | U10: USD | V10: US benchmark | W10: 46298 | X10: 0 | Y10: 0 | Z10: 0 | AA10: OpenAI public API pricing benchmark; validate Azure AI Foundry enterprise rate | AB10: List price | AC10: No discount or markup assumed; regional Azure pricing and data-residency uplift require validation. Demand executions exclude retries; the Retry % here is the single consumption uplift. No minimum commitment assumed; pricing validity is unconfirmed pending the contracted Azure rate card.
A11: AIA-002 | B11: Expected case | C11: Microsoft Azure | D11: GPT-4.1 | E11: gpt-4.1-2025-04-14 | F11: Large | G11: Primary | H11: Azure AI Foundry | I11: 1.2 | J11: 5000 | K11: 900 | L11: 500 | M11: 700 | N11: 1 | O11: 0.25 | P11: 0.06 | Q11: 2 | R11: 8 | S11: 0 | T11: N/A | U11: USD | V11: US benchmark | W11: 46298 | X11: 0 | Y11: 0 | Z11: 0 | AA11: OpenAI public API pricing benchmark; validate Azure AI Foundry enterprise rate | AB11: List price | AC11: No discount or markup assumed; regional Azure pricing and data-residency uplift require validation. Demand executions exclude retries; the Retry % here is the single consumption uplift. No minimum commitment assumed; pricing validity is unconfirmed pending the contracted Azure rate card.
A12: AIA-002 | B12: High adoption | C12: Microsoft Azure | D12: GPT-4.1 | E12: gpt-4.1-2025-04-14 | F12: Large | G12: Primary | H12: Azure AI Foundry | I12: 1.2 | J12: 5000 | K12: 900 | L12: 500 | M12: 700 | N12: 1 | O12: 0.25 | P12: 0.08 | Q12: 2 | R12: 8 | S12: 0 | T12: N/A | U12: USD | V12: US benchmark | W12: 46298 | X12: 0 | Y12: 0 | Z12: 0 | AA12: OpenAI public API pricing benchmark; validate Azure AI Foundry enterprise rate | AB12: List price | AC12: No discount or markup assumed; regional Azure pricing and data-residency uplift require validation. Demand executions exclude retries; the Retry % here is the single consumption uplift. No minimum commitment assumed; pricing validity is unconfirmed pending the contracted Azure rate card.
A13: AIA-002 | B13: Peak/stress case | C13: Microsoft Azure | D13: GPT-4.1 | E13: gpt-4.1-2025-04-14 | F13: Large | G13: Primary | H13: Azure AI Foundry | I13: 1.2 | J13: 5000 | K13: 900 | L13: 500 | M13: 700 | N13: 1 | O13: 0.25 | P13: 0.12 | Q13: 2 | R13: 8 | S13: 0 | T13: N/A | U13: USD | V13: US benchmark | W13: 46298 | X13: 0 | Y13: 0 | Z13: 0 | AA13: OpenAI public API pricing benchmark; validate Azure AI Foundry enterprise rate | AB13: List price | AC13: No discount or markup assumed; regional Azure pricing and data-residency uplift require validation. Demand executions exclude retries; the Retry % here is the single consumption uplift. No minimum commitment assumed; pricing validity is unconfirmed pending the contracted Azure rate card.
A14: AIA-002 | B14: PepsiCo standard | C14: Microsoft Azure | D14: GPT-4.1 | E14: gpt-4.1-2025-04-14 | F14: Large | G14: Primary | H14: Azure AI Foundry | I14: 1.2 | J14: 5000 | K14: 900 | L14: 500 | M14: 700 | N14: 1 | O14: 0.25 | P14: 0.07 | Q14: 2 | R14: 8 | S14: 0 | T14: N/A | U14: USD | V14: US benchmark | W14: 46298 | X14: 0 | Y14: 0 | Z14: 0 | AA14: OpenAI public API pricing benchmark; validate Azure AI Foundry enterprise rate | AB14: List price | AC14: No discount or markup assumed; regional Azure pricing and data-residency uplift require validation. Demand executions exclude retries; the Retry % here is the single consumption uplift. No minimum commitment assumed; pricing validity is unconfirmed pending the contracted Azure rate card.
A15: AIA-003 | B15: Minimum adoption | C15: Microsoft Azure | D15: GPT-4.1 mini | E15: gpt-4.1-mini-2025-04-14 | F15: Small | G15: Primary | H15: Azure AI Foundry | I15: 2 | J15: 1800 | K15: 350 | L15: 500 | M15: 700 | N15: 0 | O15: 0.25 | P15: 0.04 | Q15: 0.4 | R15: 1.6 | S15: 0 | T15: N/A | U15: USD | V15: US benchmark | W15: 46298 | X15: 0 | Y15: 0 | Z15: 0 | AA15: OpenAI public API pricing benchmark; validate Azure AI Foundry enterprise rate | AB15: List price | AC15: No discount or markup assumed; regional Azure pricing and data-residency uplift require validation. Demand executions exclude retries; the Retry % here is the single consumption uplift. No minimum commitment assumed; pricing validity is unconfirmed pending the contracted Azure rate card.
A16: AIA-003 | B16: Expected case | C16: Microsoft Azure | D16: GPT-4.1 mini | E16: gpt-4.1-mini-2025-04-14 | F16: Small | G16: Primary | H16: Azure AI Foundry | I16: 2 | J16: 1800 | K16: 350 | L16: 500 | M16: 700 | N16: 0 | O16: 0.25 | P16: 0.06 | Q16: 0.4 | R16: 1.6 | S16: 0 | T16: N/A | U16: USD | V16: US benchmark | W16: 46298 | X16: 0 | Y16: 0 | Z16: 0 | AA16: OpenAI public API pricing benchmark; validate Azure AI Foundry enterprise rate | AB16: List price | AC16: No discount or markup assumed; regional Azure pricing and data-residency uplift require validation. Demand executions exclude retries; the Retry % here is the single consumption uplift. No minimum commitment assumed; pricing validity is unconfirmed pending the contracted Azure rate card.
... A54: AIA-010 | B54: PepsiCo standard | C54: Microsoft Azure | D54: GPT-4.1 mini | E54: gpt-4.1-mini-2025-04-14 | F54: Small | G54: Primary | H54: Azure AI Foundry | I54: 2 | J54: 1800 | K54: 350 | L54: 500 | M54: 700 | N54: 0 | O54: 0.25 | P54: 0.07 | Q54: 0.4 | R54: 1.6 | S54: 0 | T54: N/A | U54: USD | V54: US benchmark | W54: 46298 | X54: 0 | Y54: 0 | Z54: 0 | AA54: OpenAI public API pricing benchmark; validate Azure AI Foundry enterprise rate | AB54: List price | AC54: No discount or markup assumed; regional Azure pricing and data-residency uplift require validation. Demand executions exclude retries; the Retry % here is the single consumption uplift. No minimum commitment assumed; pricing validity is unconfirmed pending the contracted Azure rate card.

Sheet Assumptions
A1: Partner Model For Agent Cost Estimation
A2: Pepsi Agentic Operations – 18‑Month Operating & Cost Model (Azure + LLM) | J2: BIDDER INPUT: Complete blue/yellow cells for timeline, build/adoption, workload, LLM behavior, token sizing, and token prices. Values must reflect the proposed AMS solution and be evidence-based.
A4: Timeline & Scope | F4: Build Plan (override optional)
A5: Model start month | B5: 46235 | C5: (Edit) | F5: Quarter | G5: Agents built | H5: Months
A6: Months modeled | B6: 18 | F6: Q1 | G6: 2 | H6: 3
A7: Workdays per month (avg) | B7: 21 | F7: Q2 | G7: 2 | H7: 3
A8: Region / currency | B8: USD | US benchmark; validate Azure region and enterprise agreement | F8: Q3 | G8: 2 | H8: 3
F9: Q4 | G9: 2 | H9: 3
A10: Agent Build & Adoption | F10: Q5 | G10: 0 | H10: 3
A11: Starting agents in production (existing) | B11: 2 | F11: Q6 | G11: 0 | H11: 3
A12: Agents built per quarter (avg) | B12: 2
A13: Ramp‑up: % of new agents active in month 1 | B13: 0.35 | F13: Total built (plan) | G13: =SUM(G6:G11) -> 8
A14: Ramp‑up: % active in month 2 | B14: 0.7
A15: Ramp‑up: % active in month 3+ | B15: 0.9
A16: Retirement / deprecation (% of installed base per month) | B16: 0.005
A18: Workload (Tickets & Agent Behavior)
A19: Tickets handled per active agent per workday | B19: 35
A20: Percent of tickets that are ‘self‑healing / automated fix’ | B20: 0.4
A21: Reopens / follow‑ups (% of tickets generating extra work) | B21: 0.08
A22: Avg. minutes of agent runtime per ticket (compute) | B22: 3
A24: LLM Usage (Foundry / Azure OpenAI style pricing)
A25: LLM calls per ticket (small model) | B25: 2
A26: LLM calls per ticket (large / reasoning model) | B26: 0.3
A27: Avg input tokens per small call | B27: 1800
A28: Avg output tokens per small call | B28: 350 | D28: =B28*0.8 -> 280
A29: Avg input tokens per large call | B29: 5000 | D29: =B29*0.2 -> 1000
A30: Avg output tokens per large call | B30: 900 | D30: =B30*0.2 -> 180
A31: Cache hit rate on input tokens (if supported) | B31: 0.25
A32: Retrieval / tool tokens overhead per ticket (extra input tokens) | B32: 700
A34: Unit price – small model input ($/1M tokens) | B34: 0.4
A35: Unit price – small model output ($/1M tokens) | B35: 1.6
A36: Unit price – large model input ($/1M tokens) | B36: 2
A37: Unit price – large model output ($/1M tokens) | B37: 8
A39: Platform Unit Costs
A40: All Azure / tools unit costs are in the Unit_Costs tab (editable).
A41: Notes | B41: Normalized monthly view uses portfolio-level tickets per active agent and blended LLM behavior. Demand_Scenarios uses agent-specific trigger populations and adoption; Five_Year_TCO uses those detailed scenario populations. Differences are intentional and must be revalidated with PepsiCo source data.

Sheet Unit_Costs
A1: Partner Model For Agent Cost Estimation
A2: Unit Costs & Licensing (Azure / Tools) – editable | F2: BIDDER INPUT: Replace placeholders with proposed unit rates using the stated units. Complete Notes / Source with currency, region, SKU/tier, effective date, and pricing basis.
A4: Azure platform unit costs (replace with enterprise rates)
A5: Item | B5: Value | C5: Units | D5: Notes / Source
A6: AKS node cost (blended) | B6: 350 | C6: $/node/month | D6: Partner benchmark: blended AKS VM, disk and load balancer; validate Azure SKU/region | USD | US benchmark | effective 03-Oct-2026 | planning basis only | pricing validity unconfirmed; replace with contracted rate before submission.
A7: AKS nodes per 10 active agents (baseline) | B7: 1.5 | C7: nodes / 10 agents | D7: Sizing assumption: 1.5 nodes per 10 active agents incl. resilience | USD | US benchmark | effective 03-Oct-2026 | planning basis only | pricing validity unconfirmed; replace with contracted rate before submission.
A8: Azure Functions executions per ticket | B8: 3 | C8: exec / ticket | D8: Partner architecture estimate: orchestration and tool calls | USD | US benchmark | effective 03-Oct-2026 | planning basis only | pricing validity unconfirmed; replace with contracted rate before submission.
A9: Avg GB‑seconds per Function execution | B9: 0.25 | C9: GB‑s / exec | D9: 0.5 GB memory for 0.5 second average execution | USD | US benchmark | effective 03-Oct-2026 | planning basis only | pricing validity unconfirmed; replace with contracted rate before submission.
A10: Functions price | B10: 0.2 | C10: $ / 1M exec | D10: Azure Functions Consumption list price; official Microsoft pricing | USD | US benchmark | effective 03-Oct-2026 | planning basis only | pricing validity unconfirmed; replace with contracted rate before submission.
A11: Functions price | B11: 1.6e-05 | C11: $ / GB‑s | D11: Azure Functions Consumption list price; official Microsoft pricing | USD | US benchmark | effective 03-Oct-2026 | planning basis only | pricing validity unconfirmed; replace with contracted rate before submission.
A12: Functions monthly free grant | B12: 1000000 | C12: executions | D12: Azure Functions Consumption monthly free grant | USD | US benchmark | effective 03-Oct-2026 | planning basis only | pricing validity unconfirmed; replace with contracted rate before submission.
A13: Functions monthly free grant | B13: 400000 | C13: GB‑seconds | D13: Azure Functions Consumption monthly free grant | USD | US benchmark | effective 03-Oct-2026 | planning basis only | pricing validity unconfirmed; replace with contracted rate before submission.
A14: ADLS storage cost | B14: 0.02 | C14: $ / GB‑month | D14: Partner benchmark for hot/cool storage blend; validate redundancy tier | USD | US benchmark | effective 03-Oct-2026 | planning basis only | pricing validity unconfirmed; replace with contracted rate before submission.
A15: Data lake growth | B15: 0.6 | C15: GB / 1,000 tickets | D15: Prompt, trace and artifact retention assumption | USD | US benchmark | effective 03-Oct-2026 | planning basis only | pricing validity unconfirmed; replace with contracted rate before submission.
A16: Postgres vCore cost (blended) | B16: 0.35 | C16: $ / vCore‑hr | D16: Partner benchmark for Flexible Server blended compute; validate tier and HA | USD | US benchmark | effective 03-Oct-2026 | planning basis only | pricing validity unconfirmed; replace with contracted rate before submission.
A17: Postgres storage cost | B17: 0.12 | C17: $ / GB‑month | D17: Partner benchmark for PostgreSQL storage; validate region and redundancy | USD | US benchmark | effective 03-Oct-2026 | planning basis only | pricing validity unconfirmed; replace with contracted rate before submission.
... A24: Power BI Pro cost | B24: 14 | C24: $ / user‑month | D24: Microsoft Power BI Pro public list price, paid yearly; check existing E5 entitlement | USD | US benchmark | effective 03-Oct-2026 | planning basis only | pricing validity unconfirmed; replace with contracted rate before submission.

Sheet Agent Rollout Plan
A1: APP SUPER AGENT DEPLOYMENT GANTT | J1: 26-Q3 | K1: 26-Q4 | L1: 27-Q1 | M1: 27-Q2 | T1: Super Agent | U1: Start | V1: 26-Q3 Days | W1: 26-Q4 Days | X1: 27-Q1 Days | Y1: 27-Q2 Days | Z1: 26-Q3 Cases | AA1: 26-Q4 Cases | AB1: 27-Q1 Cases | AC1: 27-Q2 Cases
A2: Filtered from '194 Automation opportunities_SH' where App/Infra = App | Schedule based on Quarter; impact based on Annual Incident Count | J2: Jul–Sep 2026 | K2: Oct–Dec 2026 | L2: Jan–Mar 2027 | M2: Apr–Jun 2027 | T2: =A6 -> Event Correlation & Alert Intelligence Agent | U2: =D6 -> #REF! | V2: =MAX(0,MIN($E6,DATE(2026,9,30))-MAX($D6,DATE(2026,6,30))) -> #REF! | W2: =MAX(0,MIN($E6,DATE(2026,12,31))-MAX($D6,DATE(2026,9,30))) -> #REF! | X2: =MAX(0,MIN($E6,DATE(2027,3,31))-MAX($D6,DATE(2026,12,31))) -> #REF! | Y2: =MAX(0,MIN($E6,DATE(2027,6,30))-MAX($D6,DATE(2027,3,31))) -> #REF! | Z2: 4 | AA2: 13 | AB2: 8 | AC2: 0
A3: App records | B3: 116 | D3: Super Agents | E3: 12 | G3: Total annual incidents | H3: 95561 | T3: =A7 -> Business Data Integrity & Reconciliation Agent | U3: =D7 -> #REF! | V3: =MAX(0,MIN($E7,DATE(2026,9,30))-MAX($D7,DATE(2026,6,30))) -> #REF! | W3: =MAX(0,MIN($E7,DATE(2026,12,31))-MAX($D7,DATE(2026,9,30))) -> #REF! | X3: =MAX(0,MIN($E7,DATE(2027,3,31))-MAX($D7,DATE(2026,12,31))) -> #REF! | Y3: =MAX(0,MIN($E7,DATE(2027,6,30))-MAX($D7,DATE(2027,3,31))) -> #REF! | Z3: 3 | AA3: 6 | AB3: 4 | AC3: 0
T4: =A8 -> Safe Auto-Remediation Agent | U4: =D8 -> #REF! | V4: =MAX(0,MIN($E8,DATE(2026,9,30))-MAX($D8,DATE(2026,6,30))) -> #REF! | W4: =MAX(0,MIN($E8,DATE(2026,12,31))-MAX($D8,DATE(2026,9,30))) -> #REF! | X4: =MAX(0,MIN($E8,DATE(2027,3,31))-MAX($D8,DATE(2026,12,31))) -> #REF! | Y4: =MAX(0,MIN($E8,DATE(2027,6,30))-MAX($D8,DATE(2027,3,31))) -> #REF! | Z4: 4 | AA4: 4 | AB4: 2 | AC4: 0
A5: Super Agent | B5: Start Quarter | C5: End Quarter | D5: Start Date | E5: End Date | F5: Duration (Days) | G5: Annual Incidents | H5: NUMBER OF USE CASES | I5: Active Quarters | T5: =A9 -> Workforce & Customer Identity Lifecycle Assistant | U5: =D9 -> #REF! | V5: =MAX(0,MIN($E9,DATE(2026,9,30))-MAX($D9,DATE(2026,6,30))) -> #REF! | W5: =MAX(0,MIN($E9,DATE(2026,12,31))-MAX($D9,DATE(2026,9,30))) -> #REF! | X5: =MAX(0,MIN($E9,DATE(2027,3,31))-MAX($D9,DATE(2026,12,31))) -> #REF! | Y5: =MAX(0,MIN($E9,DATE(2027,6,30))-MAX($D9,DATE(2027,3,31))) -> #REF! | Z5: 5 | AA5: 2 | AB5: 2 | AC5: 0
A6: Event Correlation & Alert Intelligence Agent | B6: {=_xlfn.LET(_xlpm.q,_xlfn._xlws.FILTER(#REF!,(#REF!="App")*(#REF!=$A6)),INDEX(_xlfn._xlws.SORT(_xlpm.q),1))} -> #REF! | C6: {=_xlfn.LET(_xlpm.q,_xlfn._xlws.FILTER(#REF!,(#REF!="App")*(#REF!=$A6)),INDEX(_xlfn._xlws.SORT(_xlpm.q),ROWS(_xlpm.q)))} -> #REF! | D6: =DATE(2000+LEFT(B6,2),1+(RIGHT(B6,1)-1)*3,1) -> #REF! | E6: =EDATE(DATE(2000+LEFT(C6,2),1+(RIGHT(C6,1)-1)*3,1),3)-1 -> #REF! | F6: =E6-D6+1 -> #REF! | G6: =SUMIFS(#REF!,#REF!,"App",#REF!,$A6) -> #REF! | H6: =COUNTIFS(#REF!,"App",#REF!,$A6) -> #REF! | I6: {=COUNTA(_xlfn.UNIQUE(_xlfn._xlws.FILTER(#REF!,(#REF!="App")*(#REF!=$A6))))} -> 1 | T6: =A10 -> Problem & Root-Cause Analyst | U6: =D10 -> #REF! | V6: =MAX(0,MIN($E10,DATE(2026,9,30))-MAX($D10,DATE(2026,6,30))) -> #REF! | W6: =MAX(0,MIN($E10,DATE(2026,12,31))-MAX($D10,DATE(2026,9,30))) -> #REF! | X6: =MAX(0,MIN($E10,DATE(2027,3,31))-MAX($D10,DATE(2026,12,31))) -> #REF! | Y6: =MAX(0,MIN($E10,DATE(2027,6,30))-MAX($D10,DATE(2027,3,31))) -> #REF! | Z6: 6 | AA6: 2 | AB6: 7 | AC6: 7
A7: Business Data Integrity & Reconciliation Agent | B7: {=_xlfn.LET(_xlpm.q,_xlfn._xlws.FILTER(#REF!,(#REF!="App")*(#REF!=$A7)),INDEX(_xlfn._xlws.SORT(_xlpm.q),1))} -> #REF! | C7: {=_xlfn.LET(_xlpm.q,_xlfn._xlws.FILTER(#REF!,(#REF!="App")*(#REF!=$A7)),INDEX(_xlfn._xlws.SORT(_xlpm.q),ROWS(_xlpm.q)))} -> #REF! | D7: =DATE(2000+LEFT(B7,2),1+(RIGHT(B7,1)-1)*3,1) -> #REF! | E7: =EDATE(DATE(2000+LEFT(C7,2),1+(RIGHT(C7,1)-1)*3,1),3)-1 -> #REF! | F7: =E7-D7+1 -> #REF! | G7: =SUMIFS(#REF!,#REF!,"App",#REF!,$A7) -> #REF! | H7: =COUNTIFS(#REF!,"App",#REF!,$A7) -> #REF! | I7: {=COUNTA(_xlfn.UNIQUE(_xlfn._xlws.FILTER(#REF!,(#REF!="App")*(#REF!=$A7))))} -> 1 | T7: =A11 -> Incident Triage & Major Incident Copilot | U7: =D11 -> #REF! | V7: =MAX(0,MIN($E11,DATE(2026,9,30))-MAX($D11,DATE(2026,6,30))) -> #REF! | W7: =MAX(0,MIN($E11,DATE(2026,12,31))-MAX($D11,DATE(2026,9,30))) -> #REF! | X7: =MAX(0,MIN($E11,DATE(2027,3,31))-MAX($D11,DATE(2026,12,31))) -> #REF! | Y7: =MAX(0,MIN($E11,DATE(2027,6,30))-MAX($D11,DATE(2027,3,31))) -> #REF! | Z7: 1 | AA7: 1 | AB7: 2 | AC7: 0
A8: Safe Auto-Remediation Agent | B8: {=_xlfn.LET(_xlpm.q,_xlfn._xlws.FILTER(#REF!,(#REF!="App")*(#REF!=$A8)),INDEX(_xlfn._xlws.SORT(_xlpm.q),1))} -> #REF! | C8: {=_xlfn.LET(_xlpm.q,_xlfn._xlws.FILTER(#REF!,(#REF!="App")*(#REF!=$A8)),INDEX(_xlfn._xlws.SORT(_xlpm.q),ROWS(_xlpm.q)))} -> #REF! | D8: =DATE(2000+LEFT(B8,2),1+(RIGHT(B8,1)-1)*3,1) -> #REF! | E8: =EDATE(DATE(2000+LEFT(C8,2),1+(RIGHT(C8,1)-1)*3,1),3)-1 -> #REF! | F8: =E8-D8+1 -> #REF! | G8: =SUMIFS(#REF!,#REF!,"App",#REF!,$A8) -> #REF! | H8: =COUNTIFS(#REF!,"App",#REF!,$A8) -> #REF! | I8: {=COUNTA(_xlfn.UNIQUE(_xlfn._xlws.FILTER(#REF!,(#REF!="App")*(#REF!=$A8))))} -> 1 | T8: =A12 -> Enterprise Document Intelligence & Compliance Agent | U8: =D12 -> #REF! | V8: =MAX(0,MIN($E12,DATE(2026,9,30))-MAX($D12,DATE(2026,6,30))) -> #REF! | W8: =MAX(0,MIN($E12,DATE(2026,12,31))-MAX($D12,DATE(2026,9,30))) -> #REF! | X8: =MAX(0,MIN($E12,DATE(2027,3,31))-MAX($D12,DATE(2026,12,31))) -> #REF! | Y8: =MAX(0,MIN($E12,DATE(2027,6,30))-MAX($D12,DATE(2027,3,31))) -> #REF! | Z8: 13 | AA8: 2 | AB8: 4 | AC8: 0
A9: Workforce & Customer Identity Lifecycle Assistant | B9: {=_xlfn.LET(_xlpm.q,_xlfn._xlws.FILTER(#REF!,(#REF!="App")*(#REF!=$A9)),INDEX(_xlfn._xlws.SORT(_xlpm.q),1))} -> #REF! | C9: {=_xlfn.LET(_xlpm.q,_xlfn._xlws.FILTER(#REF!,(#REF!="App")*(#REF!=$A9)),INDEX(_xlfn._xlws.SORT(_xlpm.q),ROWS(_xlpm.q)))} -> #REF! | D9: =DATE(2000+LEFT(B9,2),1+(RIGHT(B9,1)-1)*3,1) -> #REF! | E9: =EDATE(DATE(2000+LEFT(C9,2),1+(RIGHT(C9,1)-1)*3,1),3)-1 -> #REF! | F9: =E9-D9+1 -> #REF! | G9: =SUMIFS(#REF!,#REF!,"App",#REF!,$A9) -> #REF! | H9: =COUNTIFS(#REF!,"App",#REF!,$A9) -> #REF! | I9: {=COUNTA(_xlfn.UNIQUE(_xlfn._xlws.FILTER(#REF!,(#REF!="App")*(#REF!=$A9))))} -> 1 | T9: =A13 -> Operations Reporting & Insights Agent | U9: =D13 -> #REF! | V9: =MAX(0,MIN($E13,DATE(2026,9,30))-MAX($D13,DATE(2026,6,30))) -> #REF! | W9: =MAX(0,MIN($E13,DATE(2026,12,31))-MAX($D13,DATE(2026,9,30))) -> #REF! | X9: =MAX(0,MIN($E13,DATE(2027,3,31))-MAX($D13,DATE(2026,12,31))) -> #REF! | Y9: =MAX(0,MIN($E13,DATE(2027,6,30))-MAX($D13,DATE(2027,3,31))) -> #REF! | Z9: 0 | AA9: 6 | AB9: 1 | AC9: 0
A10: Problem & Root-Cause Analyst | B10: {=_xlfn.LET(_xlpm.q,_xlfn._xlws.FILTER(#REF!,(#REF!="App")*(#REF!=$A10)),INDEX(_xlfn._xlws.SORT(_xlpm.q),1))} -> #REF! | C10: {=_xlfn.LET(_xlpm.q,_xlfn._xlws.FILTER(#REF!,(#REF!="App")*(#REF!=$A10)),INDEX(_xlfn._xlws.SORT(_xlpm.q),ROWS(_xlpm.q)))} -> #REF! | D10: =DATE(2000+LEFT(B10,2),1+(RIGHT(B10,1)-1)*3,1) -> #REF! | E10: =EDATE(DATE(2000+LEFT(C10,2),1+(RIGHT(C10,1)-1)*3,1),3)-1 -> #REF! | F10: =E10-D10+1 -> #REF! | G10: =SUMIFS(#REF!,#REF!,"App",#REF!,$A10) -> #REF! | H10: =COUNTIFS(#REF!,"App",#REF!,$A10) -> #REF! | I10: {=COUNTA(_xlfn.UNIQUE(_xlfn._xlws.FILTER(#REF!,(#REF!="App")*(#REF!=$A10))))} -> 1 | T10: =A14 -> Release Quality & Validation Agent | U10: =D14 -> #REF! | V10: =MAX(0,MIN($E14,DATE(2026,9,30))-MAX($D14,DATE(2026,6,30))) -> #REF! | W10: =MAX(0,MIN($E14,DATE(2026,12,31))-MAX($D14,DATE(2026,9,30))) -> #REF! | X10: =MAX(0,MIN($E14,DATE(2027,3,31))-MAX($D14,DATE(2026,12,31))) -> #REF! | Y10: =MAX(0,MIN($E14,DATE(2027,6,30))-MAX($D14,DATE(2027,3,31))) -> #REF! | Z10: 0 | AA10: 2 | AB10: 0 | AC10: 0
